Workbook

Sheet Kết quả
N1: Dữ liệu biểu đồ (tham chiếu công thức từ các bảng trên)
B2: Kết quả định lượng – Gia Định Báo 1865–1871
B3: So sánh 3 chuyên mục Công vụ – Tạp vụ – Giá chợ giữa các giai đoạn biên tập: Ernest Potteaux (45 số) – Trương Vĩnh Ký (15 số) – G. Janneau (1 số: số 28, 01/12/1869). Nguồn: 'GDB 1866-1871'; bảng cấp số báo ở 'KQ_SoBao'. Mọi con số là công thức sống. | N3: Đơn vị theo mục | O3: Potteaux | P3: Trương Vĩnh Ký | Q3: G. Janneau
N4: Công vụ | O4: =C45 -> 217 | P4: =F45 -> 58 | Q4: =I45 -> 5
B5: 1. Tổng quan corpus | N5: Tạp vụ | O5: =C46 -> 359 | P5: =F46 -> 143 | Q5: =I46 -> 9
B6: Chỉ báo | C6: Potteaux | D6: Trương Vĩnh Ký | E6: G. Janneau | F6: Toàn corpus | N6: Giá chợ | O6: =C47 -> 97 | P6: =F47 -> 0 | Q6: =I47 -> 0
B7: Số số báo | C7: =COUNTIF(KQ_SoBao!$A:$A,"Potteaux") -> 45 | D7: =COUNTIF(KQ_SoBao!$A:$A,"TVK") -> 15 | E7: =COUNTIF(KQ_SoBao!$A:$A,"Janneau") -> 1 | F7: =C7+D7+E7 -> 61
B8: Đơn vị nội dung (3 mục) | C8: =SUMIFS(KQ_SoBao!$I:$I,KQ_SoBao!$A:$A,"Potteaux") -> 673 | D8: =SUMIFS(KQ_SoBao!$I:$I,KQ_SoBao!$A:$A,"TVK") -> 201 | E8: =SUMIFS(KQ_SoBao!$I:$I,KQ_SoBao!$A:$A,"Janneau") -> 14 | F8: =C8+D8+E8 -> 888 | N8: Tỷ trọng (đơn vị theo giai đoạn)
B9: – Công vụ | C9: =SUMIFS(KQ_SoBao!$E:$E,KQ_SoBao!$A:$A,"Potteaux") -> 217 | D9: =SUMIFS(KQ_SoBao!$E:$E,KQ_SoBao!$A:$A,"TVK") -> 58 | E9: =SUMIFS(KQ_SoBao!$E:$E,KQ_SoBao!$A:$A,"Janneau") -> 5 | F9: =C9+D9+E9 -> 280 | O9: Công vụ | P9: Tạp vụ | Q9: Giá chợ
B10: – Tạp vụ | C10: =SUMIFS(KQ_SoBao!$F:$F,KQ_SoBao!$A:$A,"Potteaux") -> 359 | D10: =SUMIFS(KQ_SoBao!$F:$F,KQ_SoBao!$A:$A,"TVK") -> 143 | E10: =SUMIFS(KQ_SoBao!$F:$F,KQ_SoBao!$A:$A,"Janneau") -> 9 | F10: =C10+D10+E10 -> 511 | N10: Potteaux | O10: =C45 -> 217 | P10: =C46 -> 359 | Q10: =C47 -> 97
B11: – Giá chợ | C11: =SUMIFS(KQ_SoBao!$G:$G,KQ_SoBao!$A:$A,"Potteaux") -> 97 | D11: =SUMIFS(KQ_SoBao!$G:$G,KQ_SoBao!$A:$A,"TVK") -> 0 | E11: =SUMIFS(KQ_SoBao!$G:$G,KQ_SoBao!$A:$A,"Janneau") -> 0 | F11: =C11+D11+E11 -> 97 | N11: Trương Vĩnh Ký | O11: =F45 -> 58 | P11: =F46 -> 143 | Q11: =F47 -> 0
B12: Phụ thêm (ngoài phân tích) | C12: =SUMIFS(KQ_SoBao!$H:$H,KQ_SoBao!$A:$A,"Potteaux") -> 10 | D12: =SUMIFS(KQ_SoBao!$H:$H,KQ_SoBao!$A:$A,"TVK") -> 1 | E12: =SUMIFS(KQ_SoBao!$H:$H,KQ_SoBao!$A:$A,"Janneau") -> 0 | F12: =C12+D12+E12 -> 11 | N12: G. Janneau | O12: =I45 -> 5 | P12: =I46 -> 9 | Q12: =I47 -> 0
B13: Đơn vị TB / số báo | C13: =C8/C7 -> 14.955556 | D13: =D8/D7 -> 13.4 | E13: =E8/E7 -> 14 | F13: =F8/F7 -> 14.557377
N14: Tỷ lệ có nhan đề gốc
B15: 2. Bảng 1 – Phân bố corpus theo năm (số số báo & hiện diện chuyên mục) | O15: Công vụ | P15: Tạp vụ
B16: Năm | C16: Số số báo | D16: Có Công vụ | E16: Có Tạp vụ | F16: Có Giá chợ | G16: Đơn vị (3 mục) | N16: Potteaux | O16: =F52 -> 0.21198157 | P16: =F55 -> 0.37325905
B17: 1865 | C17: =COUNTIF(KQ_SoBao!$D:$D,$B17) -> 3 | D17: =SUMIFS(KQ_SoBao!$J:$J,KQ_SoBao!$D:$D,$B17) -> 3 | E17: =SUMIFS(KQ_SoBao!$K:$K,KQ_SoBao!$D:$D,$B17) -> 3 | F17: =SUMIFS(KQ_SoBao!$L:$L,KQ_SoBao!$D:$D,$B17) -> 1 | G17: =SUMIFS(KQ_SoBao!$I:$I,KQ_SoBao!$D:$D,$B17) -> 57 | N17: Trương Vĩnh Ký | O17: =F53 -> 0.46551724 | P17: =F56 -> 0.79020979
B18: 1866 | C18: =COUNTIF(KQ_SoBao!$D:$D,$B18) -> 10 | D18: =SUMIFS(KQ_SoBao!$J:$J,KQ_SoBao!$D:$D,$B18) -> 10 | E18: =SUMIFS(KQ_SoBao!$K:$K,KQ_SoBao!$D:$D,$B18) -> 8 | F18: =SUMIFS(KQ_SoBao!$L:$L,KQ_SoBao!$D:$D,$B18) -> 6 | G18: =SUMIFS(KQ_SoBao!$I:$I,KQ_SoBao!$D:$D,$B18) -> 164 | N18: G. Janneau | O18: =F54 -> 1 | P18: =F57 -> 0.66666667
B19: 1867 | C19: =COUNTIF(KQ_SoBao!$D:$D,$B19) -> 12 | D19: =SUMIFS(KQ_SoBao!$J:$J,KQ_SoBao!$D:$D,$B19) -> 12 | E19: =SUMIFS(KQ_SoBao!$K:$K,KQ_SoBao!$D:$D,$B19) -> 12 | F19: =SUMIFS(KQ_SoBao!$L:$L,KQ_SoBao!$D:$D,$B19) -> 12 | G19: =SUMIFS(KQ_SoBao!$I:$I,KQ_SoBao!$D:$D,$B19) -> 215
B20: 1868 | C20: =COUNTIF(KQ_SoBao!$D:$D,$B20) -> 7 | D20: =SUMIFS(KQ_SoBao!$J:$J,KQ_SoBao!$D:$D,$B20) -> 7 | E20: =SUMIFS(KQ_SoBao!$K:$K,KQ_SoBao!$D:$D,$B20) -> 7 | F20: =SUMIFS(KQ_SoBao!$L:$L,KQ_SoBao!$D:$D,$B20) -> 7 | G20: =SUMIFS(KQ_SoBao!$I:$I,KQ_SoBao!$D:$D,$B20) -> 112 | N20: Mật độ (TB đơn vị/số)
B21: 1869 | C21: =COUNTIF(KQ_SoBao!$D:$D,$B21) -> 16 | D21: =SUMIFS(KQ_SoBao!$J:$J,KQ_SoBao!$D:$D,$B21) -> 6 | E21: =SUMIFS(KQ_SoBao!$K:$K,KQ_SoBao!$D:$D,$B21) -> 14 | F21: =SUMIFS(KQ_SoBao!$L:$L,KQ_SoBao!$D:$D,$B21) -> 0 | G21: =SUMIFS(KQ_SoBao!$I:$I,KQ_SoBao!$D:$D,$B21) -> 163 | O21: Potteaux | P21: Trương Vĩnh Ký | Q21: G. Janneau
B22: 1870 | C22: =COUNTIF(KQ_SoBao!$D:$D,$B22) -> 10 | D22: =SUMIFS(KQ_SoBao!$J:$J,KQ_SoBao!$D:$D,$B22) -> 10 | E22: =SUMIFS(KQ_SoBao!$K:$K,KQ_SoBao!$D:$D,$B22) -> 10 | F22: =SUMIFS(KQ_SoBao!$L:$L,KQ_SoBao!$D:$D,$B22) -> 0 | G22: =SUMIFS(KQ_SoBao!$I:$I,KQ_SoBao!$D:$D,$B22) -> 136 | N22: Công vụ | O22: =D45 -> 4.8222222 | P22: =G45 -> 3.8666667 | Q22: =J45 -> 5
B23: 1871 | C23: =COUNTIF(KQ_SoBao!$D:$D,$B23) -> 3 | D23: =SUMIFS(KQ_SoBao!$J:$J,KQ_SoBao!$D:$D,$B23) -> 3 | E23: =SUMIFS(KQ_SoBao!$K:$K,KQ_SoBao!$D:$D,$B23) -> 3 | F23: =SUMIFS(KQ_SoBao!$L:$L,KQ_SoBao!$D:$D,$B23) -> 0 | G23: =SUMIFS(KQ_SoBao!$I:$I,KQ_SoBao!$D:$D,$B23) -> 41 | N23: Tạp vụ | O23: =D46 -> 7.9777778 | P23: =G46 -> 9.5333333 | Q23: =J46 -> 9
B24: Tổng | C24: =SUM(C17:C23) -> 61 | D24: =SUM(D17:D23) -> 51 | E24: =SUM(E17:E23) -> 57 | F24: =SUM(F17:F23) -> 26 | G24: =SUM(G17:G23) -> 888 | N24: Giá chợ | O24: =D47 -> 2.1555556 | P24: =G47 -> 0 | Q24: =J47 -> 0
B26: 3. Bảng 2 – Hiện diện chuyên mục theo giai đoạn (cấp số báo)
B27: Chuyên mục | C27: Potteaux (số/45) | D27: % Potteaux | E27: TVK (số/15) | F27: % TVK | G27: Janneau (số/1) | H27: % Janneau | N27: Năm (biểu đồ 1) | O27: Số số báo | P27: Có Công vụ | Q27: Có Tạp vụ | R27: Có Giá chợ
B28: Công vụ | C28: =SUMIFS(KQ_SoBao!$J:$J,KQ_SoBao!$A:$A,"Potteaux") -> 35 | D28: =C28/$C$7 -> 0.77777778 | E28: =SUMIFS(KQ_SoBao!$J:$J,KQ_SoBao!$A:$A,"TVK") -> 15 | F28: =E28/$D$7 -> 1 | G28: =SUMIFS(KQ_SoBao!$J:$J,KQ_SoBao!$A:$A,"Janneau") -> 1 | H28: =G28/$E$7 -> 1 | N28: =TEXT(B17,"0") -> 1865 | O28: =C17 -> 3 | P28: =D17 -> 3 | Q28: =E17 -> 3 | R28: =F17 -> 1
B29: Tạp vụ | C29: =SUMIFS(KQ_SoBao!$K:$K,KQ_SoBao!$A:$A,"Potteaux") -> 41 | D29: =C29/$C$7 -> 0.91111111 | E29: =SUMIFS(KQ_SoBao!$K:$K,KQ_SoBao!$A:$A,"TVK") -> 15 | F29: =E29/$D$7 -> 1 | G29: =SUMIFS(KQ_SoBao!$K:$K,KQ_SoBao!$A:$A,"Janneau") -> 1 | H29: =G29/$E$7 -> 1 | N29: =TEXT(B18,"0") -> 1866 | O29: =C18 -> 10 | P29: =D18 -> 10 | Q29: =E18 -> 8 | R29: =F18 -> 6
B30: Giá chợ | C30: =SUMIFS(KQ_SoBao!$L:$L,KQ_SoBao!$A:$A,"Potteaux") -> 26 | D30: =C30/$C$7 -> 0.57777778 | E30: =SUMIFS(KQ_SoBao!$L:$L,KQ_SoBao!$A:$A,"TVK") -> 0 | F30: =E30/$D$7 -> 0 | G30: =SUMIFS(KQ_SoBao!$L:$L,KQ_SoBao!$A:$A,"Janneau") -> 0 | H30: =G30/$E$7 -> 0 | N30: =TEXT(B19,"0") -> 1867 | O30: =C19 -> 12 | P30: =D19 -> 12 | Q30: =E19 -> 12 | R30: =F19 -> 12
N31: =TEXT(B20,"0") -> 1868 | O31: =C20 -> 7 | P31: =D20 -> 7 | Q31: =E20 -> 7 | R31: =F20 -> 7
B32: 4. Bảng 3 – Mẫu tổ hợp chuyên mục trong mỗi số báo | N32: =TEXT(B21,"0") -> 1869 | O32: =C21 -> 16 | P32: =D21 -> 6 | Q32: =E21 -> 14 | R32: =F21 -> 0
B33: Tổ hợp | C33: Potteaux | D33: TVK | E33: Janneau | N33: =TEXT(B22,"0") -> 1870 | O33: =C22 -> 10 | P33: =D22 -> 10 | Q33: =E22 -> 10 | R33: =F22 -> 0
B34: Công vụ + Tạp vụ + Giá chợ | C34: =COUNTIFS(KQ_SoBao!$M:$M,"CV+TV+GC",KQ_SoBao!$A:$A,"Potteaux") -> 24 | D34: =COUNTIFS(KQ_SoBao!$M:$M,"CV+TV+GC",KQ_SoBao!$A:$A,"TVK") -> 0 | E34: =COUNTIFS(KQ_SoBao!$M:$M,"CV+TV+GC",KQ_SoBao!$A:$A,"Janneau") -> 0 | N34: =TEXT(B23,"0") -> 1871 | O34: =C23 -> 3 | P34: =D23 -> 3 | Q34: =E23 -> 3 | R34: =F23 -> 0
B35: Công vụ + Tạp vụ | C35: =COUNTIFS(KQ_SoBao!$M:$M,"CV+TV",KQ_SoBao!$A:$A,"Potteaux") -> 7 | D35: =COUNTIFS(KQ_SoBao!$M:$M,"CV+TV",KQ_SoBao!$A:$A,"TVK") -> 15 | E35: =COUNTIFS(KQ_SoBao!$M:$M,"CV+TV",KQ_SoBao!$A:$A,"Janneau") -> 1
B36: Công vụ + Giá chợ | C36: =COUNTIFS(KQ_SoBao!$M:$M,"CV+GC",KQ_SoBao!$A:$A,"Potteaux") -> 2 | D36: =COUNTIFS(KQ_SoBao!$M:$M,"CV+GC",KQ_SoBao!$A:$A,"TVK") -> 0 | E36: =COUNTIFS(KQ_SoBao!$M:$M,"CV+GC",KQ_SoBao!$A:$A,"Janneau") -> 0
B37: Tạp vụ + Giá chợ | C37: =COUNTIFS(KQ_SoBao!$M:$M,"TV+GC",KQ_SoBao!$A:$A,"Potteaux") -> 0 | D37: =COUNTIFS(KQ_SoBao!$M:$M,"TV+GC",KQ_SoBao!$A:$A,"TVK") -> 0 | E37: =COUNTIFS(KQ_SoBao!$M:$M,"TV+GC",KQ_SoBao!$A:$A,"Janneau") -> 0
B38: Chỉ Công vụ | C38: =COUNTIFS(KQ_SoBao!$M:$M,"CV",KQ_SoBao!$A:$A,"Potteaux") -> 2 | D38: =COUNTIFS(KQ_SoBao!$M:$M,"CV",KQ_SoBao!$A:$A,"TVK") -> 0 | E38: =COUNTIFS(KQ_SoBao!$M:$M,"CV",KQ_SoBao!$A:$A,"Janneau") -> 0
B39: Chỉ Tạp vụ | C39: =COUNTIFS(KQ_SoBao!$M:$M,"TV",KQ_SoBao!$A:$A,"Potteaux") -> 10 | D39: =COUNTIFS(KQ_SoBao!$M:$M,"TV",KQ_SoBao!$A:$A,"TVK") -> 0 | E39: =COUNTIFS(KQ_SoBao!$M:$M,"TV",KQ_SoBao!$A:$A,"Janneau") -> 0
B40: Chỉ Giá chợ | C40: =COUNTIFS(KQ_SoBao!$M:$M,"GC",KQ_SoBao!$A:$A,"Potteaux") -> 0 | D40: =COUNTIFS(KQ_SoBao!$M:$M,"GC",KQ_SoBao!$A:$A,"TVK") -> 0 | E40: =COUNTIFS(KQ_SoBao!$M:$M,"GC",KQ_SoBao!$A:$A,"Janneau") -> 0
B41: Tổng | C41: =SUM(C34:C40) -> 45 | D41: =SUM(D34:D40) -> 15 | E41: =SUM(E34:E40) -> 1
...

Sheet TK bản thảo
B1: Thống kê theo bản thảo hội thảo – Gia Định Báo 1865–1871 | J1: Mẫu số phụ trợ
B2: So sánh Potteaux (45 số / 673 đv) vs Trương Vĩnh Ký (15 số / 201 đv); số Janneau (28) là ca chuyển tiếp bổ trợ. Công thức sống từ 'GDB 1866-1871' & 'KQ_SoBao'. | J2: Tạp vụ · Potteaux | K2: =COUNTIFS('GDB 1866-1871'!$R:$R,"Potteaux",'GDB 1866-1871'!$T:$T,"Tạp vụ") -> 359
B3: Bảng 1. Phân bố corpus 1865–1871 theo năm | J3: Tạp vụ · TVK | K3: =COUNTIFS('GDB 1866-1871'!$R:$R,"TVK",'GDB 1866-1871'!$T:$T,"Tạp vụ") -> 143
B4: Năm | C4: Số báo | D4: Có Công vụ | E4: Có Tạp vụ | F4: Có Giá chợ | G4: Đơn vị 3 mục | J4: Công vụ · Potteaux | K4: =COUNTIFS('GDB 1866-1871'!$R:$R,"Potteaux",'GDB 1866-1871'!$T:$T,"Công vụ") -> 217
B5: 1865 | C5: =COUNTIF(KQ_SoBao!$D:$D,$B5) -> 3 | D5: =SUMIFS(KQ_SoBao!$J:$J,KQ_SoBao!$D:$D,$B5) -> 3 | E5: =SUMIFS(KQ_SoBao!$K:$K,KQ_SoBao!$D:$D,$B5) -> 3 | F5: =SUMIFS(KQ_SoBao!$L:$L,KQ_SoBao!$D:$D,$B5) -> 1 | G5: =SUMIFS(KQ_SoBao!$I:$I,KQ_SoBao!$D:$D,$B5) -> 57 | J5: Công vụ · TVK | K5: =COUNTIFS('GDB 1866-1871'!$R:$R,"TVK",'GDB 1866-1871'!$T:$T,"Công vụ") -> 58
B6: 1866 | C6: =COUNTIF(KQ_SoBao!$D:$D,$B6) -> 10 | D6: =SUMIFS(KQ_SoBao!$J:$J,KQ_SoBao!$D:$D,$B6) -> 10 | E6: =SUMIFS(KQ_SoBao!$K:$K,KQ_SoBao!$D:$D,$B6) -> 8 | F6: =SUMIFS(KQ_SoBao!$L:$L,KQ_SoBao!$D:$D,$B6) -> 6 | G6: =SUMIFS(KQ_SoBao!$I:$I,KQ_SoBao!$D:$D,$B6) -> 164
B7: 1867 | C7: =COUNTIF(KQ_SoBao!$D:$D,$B7) -> 12 | D7: =SUMIFS(KQ_SoBao!$J:$J,KQ_SoBao!$D:$D,$B7) -> 12 | E7: =SUMIFS(KQ_SoBao!$K:$K,KQ_SoBao!$D:$D,$B7) -> 12 | F7: =SUMIFS(KQ_SoBao!$L:$L,KQ_SoBao!$D:$D,$B7) -> 12 | G7: =SUMIFS(KQ_SoBao!$I:$I,KQ_SoBao!$D:$D,$B7) -> 215
B8: 1868 | C8: =COUNTIF(KQ_SoBao!$D:$D,$B8) -> 7 | D8: =SUMIFS(KQ_SoBao!$J:$J,KQ_SoBao!$D:$D,$B8) -> 7 | E8: =SUMIFS(KQ_SoBao!$K:$K,KQ_SoBao!$D:$D,$B8) -> 7 | F8: =SUMIFS(KQ_SoBao!$L:$L,KQ_SoBao!$D:$D,$B8) -> 7 | G8: =SUMIFS(KQ_SoBao!$I:$I,KQ_SoBao!$D:$D,$B8) -> 112 | J8: Hình thức (Tạp vụ) | K8: Potteaux % | L8: TVK %
B9: 1869 | C9: =COUNTIF(KQ_SoBao!$D:$D,$B9) -> 16 | D9: =SUMIFS(KQ_SoBao!$J:$J,KQ_SoBao!$D:$D,$B9) -> 6 | E9: =SUMIFS(KQ_SoBao!$K:$K,KQ_SoBao!$D:$D,$B9) -> 14 | F9: =SUMIFS(KQ_SoBao!$L:$L,KQ_SoBao!$D:$D,$B9) -> 0 | G9: =SUMIFS(KQ_SoBao!$I:$I,KQ_SoBao!$D:$D,$B9) -> 163 | J9: =B23 -> Tin – tường thuật sự kiện | K9: =D23 -> 0.41504178 | L9: =F23 -> 0.44755245
B10: 1870 | C10: =COUNTIF(KQ_SoBao!$D:$D,$B10) -> 10 | D10: =SUMIFS(KQ_SoBao!$J:$J,KQ_SoBao!$D:$D,$B10) -> 10 | E10: =SUMIFS(KQ_SoBao!$K:$K,KQ_SoBao!$D:$D,$B10) -> 10 | F10: =SUMIFS(KQ_SoBao!$L:$L,KQ_SoBao!$D:$D,$B10) -> 0 | G10: =SUMIFS(KQ_SoBao!$I:$I,KQ_SoBao!$D:$D,$B10) -> 136 | J10: =B24 -> Tin tổng hợp | K10: =D24 -> 0.10306407 | L10: =F24 -> 0.048951049
B11: 1871 | C11: =COUNTIF(KQ_SoBao!$D:$D,$B11) -> 3 | D11: =SUMIFS(KQ_SoBao!$J:$J,KQ_SoBao!$D:$D,$B11) -> 3 | E11: =SUMIFS(KQ_SoBao!$K:$K,KQ_SoBao!$D:$D,$B11) -> 3 | F11: =SUMIFS(KQ_SoBao!$L:$L,KQ_SoBao!$D:$D,$B11) -> 0 | G11: =SUMIFS(KQ_SoBao!$I:$I,KQ_SoBao!$D:$D,$B11) -> 41 | J11: =B25 -> Văn bản công quyền – quy phạm – quyết định | K11: =D25 -> 0.022284123 | L11: =F25 -> 0
B12: Tổng | C12: =SUM(C5:C11) -> 61 | D12: =SUM(D5:D11) -> 51 | E12: =SUM(E5:E11) -> 57 | F12: =SUM(F5:F11) -> 26 | G12: =SUM(G5:G11) -> 888 | J12: =B26 -> Thông báo – yết thị | K12: =D26 -> 0.038997214 | L12: =F26 -> 0.027972028
J13: =B27 -> Lời rao – quảng cáo – đấu giá – đấu thầu | K13: =D27 -> 0.036211699 | L13: =F27 -> 0.041958042
B14: Bảng 2. Các chỉ báo chính theo giai đoạn Potteaux & Trương Vĩnh Ký | J14: =B28 -> Bảng giá – bảng kê – danh sách – thống kê | K14: =D28 -> 0.091922006 | L14: =F28 -> 0.12587413
B15: Chuyên mục | C15: Potteaux n | D15: TB/số | E15: Tỷ trọng | F15: TVK n | G15: TB/số | H15: Tỷ trọng | J15: =B29 -> Bài tri thức – khảo cứu – giải thích | K15: =D29 -> 0.075208914 | L15: =F29 -> 0.20979021
B16: Công vụ | C16: =COUNTIFS('GDB 1866-1871'!$R:$R,"Potteaux",'GDB 1866-1871'!$T:$T,$B16) -> 217 | D16: =C16/COUNTIF(KQ_SoBao!$A:$A,"Potteaux") -> 4.8222222 | E16: =C16/$C$19 -> 0.32243685 | F16: =COUNTIFS('GDB 1866-1871'!$R:$R,"TVK",'GDB 1866-1871'!$T:$T,$B16) -> 58 | G16: =F16/COUNTIF(KQ_SoBao!$A:$A,"TVK") -> 3.8666667 | H16: =F16/$F$19 -> 0.28855721 | J16: =B30 -> Nghị luận – bình luận – khuyến dụ – giáo huấn | K16: =D30 -> 0.050139276 | L16: =F30 -> 0.083916084
B17: Tạp vụ | C17: =COUNTIFS('GDB 1866-1871'!$R:$R,"Potteaux",'GDB 1866-1871'!$T:$T,$B17) -> 359 | D17: =C17/COUNTIF(KQ_SoBao!$A:$A,"Potteaux") -> 7.9777778 | E17: =C17/$C$19 -> 0.53343239 | F17: =COUNTIFS('GDB 1866-1871'!$R:$R,"TVK",'GDB 1866-1871'!$T:$T,$B17) -> 143 | G17: =F17/COUNTIF(KQ_SoBao!$A:$A,"TVK") -> 9.5333333 | H17: =F17/$F$19 -> 0.71144279 | J17: =B31 -> Truyện – văn chương | K17: =D31 -> 0.1281337 | L17: =F31 -> 0.006993007
B18: Giá chợ | C18: =COUNTIFS('GDB 1866-1871'!$R:$R,"Potteaux",'GDB 1866-1871'!$T:$T,$B18) -> 97 | D18: =C18/COUNTIF(KQ_SoBao!$A:$A,"Potteaux") -> 2.1555556 | E18: =C18/$C$19 -> 0.14413076 | F18: =COUNTIFS('GDB 1866-1871'!$R:$R,"TVK",'GDB 1866-1871'!$T:$T,$B18) -> 0 | G18: =F18/COUNTIF(KQ_SoBao!$A:$A,"TVK") -> 0 | H18: =F18/$F$19 -> 0 | J18: =B32 -> Thư từ – văn thư – báo cáo đăng nguyên dạng | K18: =D32 -> 0.022284123 | L18: =F32 -> 0.006993007
B19: Tổng | C19: =SUM(C16:C18) -> 673 | D19: =C19/COUNTIF(KQ_SoBao!$A:$A,"Potteaux") -> 14.955556 | E19: =C19/$C$19 -> 1 | F19: =SUM(F16:F18) -> 201 | G19: =F19/COUNTIF(KQ_SoBao!$A:$A,"TVK") -> 13.4 | H19: =F19/$F$19 -> 1 | J19: =B33 -> Hỏi đáp – bảng hỏi – đối thoại – phỏng vấn | K19: =D33 -> 0.016713092 | L19: =F33 -> 0
B21: Bảng 3. Hình thức chính trong Tạp vụ theo hai giai đoạn | J21: Nội dung (Tạp vụ) | K21: Potteaux % | L21: TVK %
B22: Hình thức chính (Tạp vụ) | C22: Potteaux n | D22: % | E22: TVK n | F22: % | J22: =B38 -> Chính trị – hành chính | K22: =D38 -> 0.044568245 | L22: =F38 -> 0.020979021
B23: ='Kết quả'!B80 -> Tin – tường thuật sự kiện | C23: =COUNTIFS('GDB 1866-1871'!$R:$R,"Potteaux",'GDB 1866-1871'!$T:$T,"Tạp vụ",'GDB 1866-1871'!$G:$G,$B23) -> 149 | D23: =C23/$K$2 -> 0.41504178 | E23: =COUNTIFS('GDB 1866-1871'!$R:$R,"TVK",'GDB 1866-1871'!$T:$T,"Tạp vụ",'GDB 1866-1871'!$G:$G,$B23) -> 64 | F23: =E23/$K$3 -> 0.44755245 | J23: =B39 -> Pháp luật – tư pháp – an ninh | K23: =D39 -> 0.13927577 | L23: =F39 -> 0.090909091
B24: ='Kết quả'!B81 -> Tin tổng hợp | C24: =COUNTIFS('GDB 1866-1871'!$R:$R,"Potteaux",'GDB 1866-1871'!$T:$T,"Tạp vụ",'GDB 1866-1871'!$G:$G,$B24) -> 37 | D24: =C24/$K$2 -> 0.10306407 | E24: =COUNTIFS('GDB 1866-1871'!$R:$R,"TVK",'GDB 1866-1871'!$T:$T,"Tạp vụ",'GDB 1866-1871'!$G:$G,$B24) -> 7 | F24: =E24/$K$3 -> 0.048951049 | J24: =B40 -> Quân sự – chiến sự | K24: =D40 -> 0.094707521 | L24: =F40 -> 0
B25: ='Kết quả'!B82 -> Văn bản công quyền – quy phạm – quyết định | C25: =COUNTIFS('GDB 1866-1871'!$R:$R,"Potteaux",'GDB 1866-1871'!$T:$T,"Tạp vụ",'GDB 1866-1871'!$G:$G,$B25) -> 8 | D25: =C25/$K$2 -> 0.022284123 | E25: =COUNTIFS('GDB 1866-1871'!$R:$R,"TVK",'GDB 1866-1871'!$T:$T,"Tạp vụ",'GDB 1866-1871'!$G:$G,$B25) -> 0 | F25: =E25/$K$3 -> 0 | J25: =B41 -> Ngoại giao – quan hệ đối ngoại | K25: =D41 -> 0.019498607 | L25: =F41 -> 0
B26: ='Kết quả'!B83 -> Thông báo – yết thị | C26: =COUNTIFS('GDB 1866-1871'!$R:$R,"Potteaux",'GDB 1866-1871'!$T:$T,"Tạp vụ",'GDB 1866-1871'!$G:$G,$B26) -> 14 | D26: =C26/$K$2 -> 0.038997214 | E26: =COUNTIFS('GDB 1866-1871'!$R:$R,"TVK",'GDB 1866-1871'!$T:$T,"Tạp vụ",'GDB 1866-1871'!$G:$G,$B26) -> 4 | F26: =E26/$K$3 -> 0.027972028 | J26: =B42 -> Kinh tế – tài chính – thương mại | K26: =D42 -> 0.15041783 | L26: =F42 -> 0.12587413
B27: ='Kết quả'!B84 -> Lời rao – quảng cáo – đấu giá – đấu thầu | C27: =COUNTIFS('GDB 1866-1871'!$R:$R,"Potteaux",'GDB 1866-1871'!$T:$T,"Tạp vụ",'GDB 1866-1871'!$G:$G,$B27) -> 13 | D27: =C27/$K$2 -> 0.036211699 | E27: =COUNTIFS('GDB 1866-1871'!$R:$R,"TVK",'GDB 1866-1871'!$T:$T,"Tạp vụ",'GDB 1866-1871'!$G:$G,$B27) -> 6 | F27: =E27/$K$3 -> 0.041958042 | J27: =B43 -> Nông nghiệp – sản xuất – nghề nghiệp | K27: =D43 -> 0.036211699 | L27: =F43 -> 0.020979021
B28: ='Kết quả'!B85 -> Bảng giá – bảng kê – danh sách – thống kê | C28: =COUNTIFS('GDB 1866-1871'!$R:$R,"Potteaux",'GDB 1866-1871'!$T:$T,"Tạp vụ",'GDB 1866-1871'!$G:$G,$B28) -> 33 | D28: =C28/$K$2 -> 0.091922006 | E28: =COUNTIFS('GDB 1866-1871'!$R:$R,"TVK",'GDB 1866-1871'!$T:$T,"Tạp vụ",'GDB 1866-1871'!$G:$G,$B28) -> 18 | F28: =E28/$K$3 -> 0.12587413 | J28: =B44 -> Giao thông – tàu thuyền – liên lạc | K28: =D44 -> 0.0055710306 | L28: =F44 -> 0.041958042
B29: ='Kết quả'!B86 -> Bài tri thức – khảo cứu – giải thích | C29: =COUNTIFS('GDB 1866-1871'!$R:$R,"Potteaux",'GDB 1866-1871'!$T:$T,"Tạp vụ",'GDB 1866-1871'!$G:$G,$B29) -> 27 | D29: =C29/$K$2 -> 0.075208914 | E29: =COUNTIFS('GDB 1866-1871'!$R:$R,"TVK",'GDB 1866-1871'!$T:$T,"Tạp vụ",'GDB 1866-1871'!$G:$G,$B29) -> 30 | F29: =E29/$K$3 -> 0.20979021 | J29: =B45 -> Y tế – sức khỏe | K29: =D45 -> 0.013927577 | L29: =F45 -> 0
B30: ='Kết quả'!B87 -> Nghị luận – bình luận – khuyến dụ – giáo huấn | C30: =COUNTIFS('GDB 1866-1871'!$R:$R,"Potteaux",'GDB 1866-1871'!$T:$T,"Tạp vụ",'GDB 1866-1871'!$G:$G,$B30) -> 18 | D30: =C30/$K$2 -> 0.050139276 | E30: =COUNTIFS('GDB 1866-1871'!$R:$R,"TVK",'GDB 1866-1871'!$T:$T,"Tạp vụ",'GDB 1866-1871'!$G:$G,$B30) -> 12 | F30: =E30/$K$3 -> 0.083916084 | J30: =B46 -> Giáo dục – khoa cử | K30: =D46 -> 0.04178273 | L30: =F46 -> 0.006993007
B31: ='Kết quả'!B88 -> Truyện – văn chương | C31: =COUNTIFS('GDB 1866-1871'!$R:$R,"Potteaux",'GDB 1866-1871'!$T:$T,"Tạp vụ",'GDB 1866-1871'!$G:$G,$B31) -> 46 | D31: =C31/$K$2 -> 0.1281337 | E31: =COUNTIFS('GDB 1866-1871'!$R:$R,"TVK",'GDB 1866-1871'!$T:$T,"Tạp vụ",'GDB 1866-1871'!$G:$G,$B31) -> 1 | F31: =E31/$K$3 -> 0.006993007 | J31: =B47 -> Văn hóa – xã hội – phong tục – đời sống | K31: =D47 -> 0.18384401 | L31: =F47 -> 0.16783217
B32: ='Kết quả'!B89 -> Thư từ – văn thư – báo cáo đăng nguyên dạng | C32: =COUNTIFS('GDB 1866-1871'!$R:$R,"Potteaux",'GDB 1866-1871'!$T:$T,"Tạp vụ",'GDB 1866-1871'!$G:$G,$B32) -> 8 | D32: =C32/$K$2 -> 0.022284123 | E32: =COUNTIFS('GDB 1866-1871'!$R:$R,"TVK",'GDB 1866-1871'!$T:$T,"Tạp vụ",'GDB 1866-1871'!$G:$G,$B32) -> 1 | F32: =E32/$K$3 -> 0.006993007 | J32: =B48 -> Tôn giáo – tín ngưỡng | K32: =D48 -> 0.011142061 | L32: =F48 -> 0.013986014
B33: ='Kết quả'!B90 -> Hỏi đáp – bảng hỏi – đối thoại – phỏng vấn | C33: =COUNTIFS('GDB 1866-1871'!$R:$R,"Potteaux",'GDB 1866-1871'!$T:$T,"Tạp vụ",'GDB 1866-1871'!$G:$G,$B33) -> 6 | D33: =C33/$K$2 -> 0.016713092 | E33: =COUNTIFS('GDB 1866-1871'!$R:$R,"TVK",'GDB 1866-1871'!$T:$T,"Tạp vụ",'GDB 1866-1871'!$G:$G,$B33) -> 0 | F33: =E33/$K$3 -> 0 | J33: =B49 -> Lịch sử – địa lý | K33: =D49 -> 0.04735376 | L33: =F49 -> 0.15384615
B34: Tổng | C34: =SUM(C23:C33) -> 359 | D34: =C34/$K$2 -> 1 | E34: =SUM(E23:E33) -> 143 | F34: =E34/$K$3 -> 1 | J34: =B50 -> Khoa học – kỹ thuật | K34: =D50 -> 0.016713092 | L34: =F50 -> 0.006993007
J35: =B51 -> Tai nạn – thiên tai – sự cố | K35: =D51 -> 0.091922006 | L35: =F51 -> 0.27972028
B36: Bảng 4. Nội dung chính trong Tạp vụ theo hai giai đoạn | J36: =B52 -> Báo chí – xuất bản – truyền thông | K36: =D52 -> 0.013927577 | L36: =F52 -> 0.041958042
B37: Nội dung chính (Tạp vụ) | C37: Potteaux n | D37: % | E37: TVK n | F37: % | J37: =B53 -> Đa chủ đề | K37: =D53 -> 0.08913649 | L37: =F53 -> 0.027972028
B38: ='Kết quả'!B95 -> Chính trị – hành chính | C38: =COUNTIFS('GDB 1866-1871'!$R:$R,"Potteaux",'GDB 1866-1871'!$T:$T,"Tạp vụ",'GDB 1866-1871'!$I:$I,$B38) -> 16 | D38: =C38/$K$2 -> 0.044568245 | E38: =COUNTIFS('GDB 1866-1871'!$R:$R,"TVK",'GDB 1866-1871'!$T:$T,"Tạp vụ",'GDB 1866-1871'!$I:$I,$B38) -> 3 | F38: =E38/$K$3 -> 0.020979021
B39: ='Kết quả'!B96 -> Pháp luật – tư pháp – an ninh | C39: =COUNTIFS('GDB 1866-1871'!$R:$R,"Potteaux",'GDB 1866-1871'!$T:$T,"Tạp vụ",'GDB 1866-1871'!$I:$I,$B39) -> 50 | D39: =C39/$K$2 -> 0.13927577 | E39: =COUNTIFS('GDB 1866-1871'!$R:$R,"TVK",'GDB 1866-1871'!$T:$T,"Tạp vụ",'GDB 1866-1871'!$I:$I,$B39) -> 13 | F39: =E39/$K$3 -> 0.090909091 | J39: Chuyên mục | K39: Potteaux | L39: TVK
B40: ='Kết quả'!B97 -> Quân sự – chiến sự | C40: =COUNTIFS('GDB 1866-1871'!$R:$R,"Potteaux",'GDB 1866-1871'!$T:$T,"Tạp vụ",'GDB 1866-1871'!$I:$I,$B40) -> 34 | D40: =C40/$K$2 -> 0.094707521 | E40: =COUNTIFS('GDB 1866-1871'!$R:$R,"TVK",'GDB 1866-1871'!$T:$T,"Tạp vụ",'GDB 1866-1871'!$I:$I,$B40) -> 0 | F40: =E40/$K$3 -> 0 | J40: =B16 -> Công vụ | K40: =E16 -> 0.32243685 | L40: =H16 -> 0.28855721
B41: ='Kết quả'!B98 -> Ngoại giao – quan hệ đối ngoại | C41: =COUNTIFS('GDB 1866-1871'!$R:$R,"Potteaux",'GDB 1866-1871'!$T:$T,"Tạp vụ",'GDB 1866-1871'!$I:$I,$B41) -> 7 | D41: =C41/$K$2 -> 0.019498607 | E41: =COUNTIFS('GDB 1866-1871'!$R:$R,"TVK",'GDB 1866-1871'!$T:$T,"Tạp vụ",'GDB 1866-1871'!$I:$I,$B41) -> 0 | F41: =E41/$K$3 -> 0 | J41: =B17 -> Tạp vụ | K41: =E17 -> 0.53343239 | L41: =H17 -> 0.71144279
...

Sheet Kết quả (đề xuất)
B1: KẾ T QUẢ (đề xuất) – Gia Định Báo 1865–1871
B2: Cách trình bày kết quả bám 3 câu hỏi nghiên cứu; đo độ lớn thay đổi bằng Đ (điểm %) & tỉ số; bổ sung so sánh 3 pha và dòng thời gian 1869 để tách mốc thể chế khỏi mốc biến đổi nội dung.
B4: Câu hỏi 1 – Cấu trúc: Công vụ–Tạp vụ–Giá chợ biến đổi ra sao quanh mốc 1869?
B5: Câu hỏi 2 – Hình thức: cơ cấu hình thức Công vụ & Tạp vụ khác nhau thế nào?
B6: Câu hỏi 3 – Nội dung & thời điểm: Tạp vụ tái phân bố chủ đề ra sao; “phong phú hóa” hiểu theo nghĩa nào?
B8: A. Chỉ báo tổng hợp: Potteaux vs Trương Vĩnh Ký
B9: Chỉ báo | C9: Potteaux | D9: TVK | E9: Đ (TVK − Pott)
B10: Số số báo | C10: =COUNTIF(KQ_SoBao!$A:$A,"Potteaux") -> 45 | D10: =COUNTIF(KQ_SoBao!$A:$A,"TVK") -> 15 | E10: =D10-C10 -> -30
B11: Đơn vị 3 mục | C11: ='TK bản thảo'!C19 -> 673 | D11: ='TK bản thảo'!F19 -> 201 | E11: =D11-C11 -> -472
B12: Mật độ 3 mục (đv/số) | C12: ='TK bản thảo'!D19 -> 14.955556 | D12: ='TK bản thảo'!G19 -> 13.4 | E12: =D12-C12 -> -1.5555556
B13: Mật độ Công vụ+Tạp vụ (đv/số) | C13: =('TK bản thảo'!C16+'TK bản thảo'!C17)/C10 -> 12.8 | D13: =('TK bản thảo'!F16+'TK bản thảo'!F17)/D10 -> 13.4 | E13: =D13-C13 -> 0.6
B14: Tỷ trọng Tạp vụ (trong 3 mục) | C14: ='TK bản thảo'!E17 -> 0.53343239 | D14: ='TK bản thảo'!H17 -> 0.71144279 | E14: =D14-C14 -> 0.17801039
B15: Mật độ Công vụ (đv/số) | C15: ='TK bản thảo'!D16 -> 4.8222222 | D15: ='TK bản thảo'!G16 -> 3.8666667 | E15: =D15-C15 -> -0.95555556
B16: Hiện diện Công vụ (% số báo) | C16: =SUMIFS(KQ_SoBao!$J:$J,KQ_SoBao!$A:$A,"Potteaux")/C10 -> 0.77777778 | D16: =SUMIFS(KQ_SoBao!$J:$J,KQ_SoBao!$A:$A,"TVK")/D10 -> 1 | E16: =D16-C16 -> 0.22222222
B17: Nhan đề gốc Công vụ+Tạp vụ (%) | C17: ='TK bản thảo'!E60 -> 0.3125 | D17: ='TK bản thảo'!H60 -> 0.69651741 | E17: =D17-C17 -> 0.38401741
B19: B. Tạp vụ – tái phân bố Hình thức (% trong Tạp vụ mỗi giai đoạn)
B20: Hình thức chính | C20: Potteaux % | D20: TVK % | E20: Đ (điểm %) | F20: Tỉ số TVK/Pott
B21: ='TK bản thảo'!B23 -> Tin – tường thuật sự kiện | C21: ='TK bản thảo'!D23 -> 0.41504178 | D21: ='TK bản thảo'!F23 -> 0.44755245 | E21: =D21-C21 -> 0.032510665 | F21: =IF(C21=0,"–",D21/C21) -> 1.0783311
B22: ='TK bản thảo'!B24 -> Tin tổng hợp | C22: ='TK bản thảo'!D24 -> 0.10306407 | D22: ='TK bản thảo'!F24 -> 0.048951049 | E22: =D22-C22 -> -0.054113018 | F22: =IF(C22=0,"–",D22/C22) -> 0.47495747
B23: ='TK bản thảo'!B25 -> Văn bản công quyền – quy phạm – quyết định | C23: ='TK bản thảo'!D25 -> 0.022284123 | D23: ='TK bản thảo'!F25 -> 0 | E23: =D23-C23 -> -0.022284123 | F23: =IF(C23=0,"–",D23/C23) -> 0
B24: ='TK bản thảo'!B26 -> Thông báo – yết thị | C24: ='TK bản thảo'!D26 -> 0.038997214 | D24: ='TK bản thảo'!F26 -> 0.027972028 | E24: =D24-C24 -> -0.011025187 | F24: =IF(C24=0,"–",D24/C24) -> 0.71728272
B25: ='TK bản thảo'!B27 -> Lời rao – quảng cáo – đấu giá – đấu thầu | C25: ='TK bản thảo'!D27 -> 0.036211699 | D25: ='TK bản thảo'!F27 -> 0.041958042 | E25: =D25-C25 -> 0.0057463428 | F25: =IF(C25=0,"–",D25/C25) -> 1.1586875
B26: ='TK bản thảo'!B28 -> Bảng giá – bảng kê – danh sách – thống kê | C26: ='TK bản thảo'!D28 -> 0.091922006 | D26: ='TK bản thảo'!F28 -> 0.12587413 | E26: =D26-C26 -> 0.03395212 | F26: =IF(C26=0,"–",D26/C26) -> 1.3693579
B27: ='TK bản thảo'!B29 -> Bài tri thức – khảo cứu – giải thích | C27: ='TK bản thảo'!D29 -> 0.075208914 | D27: ='TK bản thảo'!F29 -> 0.20979021 | E27: =D27-C27 -> 0.1345813 | F27: =IF(C27=0,"–",D27/C27) -> 2.7894328
B28: ='TK bản thảo'!B30 -> Nghị luận – bình luận – khuyến dụ – giáo huấn | C28: ='TK bản thảo'!D30 -> 0.050139276 | D28: ='TK bản thảo'!F30 -> 0.083916084 | E28: =D28-C28 -> 0.033776808 | F28: =IF(C28=0,"–",D28/C28) -> 1.6736597
B29: ='TK bản thảo'!B31 -> Truyện – văn chương | C29: ='TK bản thảo'!D31 -> 0.1281337 | D29: ='TK bản thảo'!F31 -> 0.006993007 | E29: =D29-C29 -> -0.1211407 | F29: =IF(C29=0,"–",D29/C29) -> 0.054575859
B30: ='TK bản thảo'!B32 -> Thư từ – văn thư – báo cáo đăng nguyên dạng | C30: ='TK bản thảo'!D32 -> 0.022284123 | D30: ='TK bản thảo'!F32 -> 0.006993007 | E30: =D30-C30 -> -0.015291116 | F30: =IF(C30=0,"–",D30/C30) -> 0.31381119
B31: ='TK bản thảo'!B33 -> Hỏi đáp – bảng hỏi – đối thoại – phỏng vấn | C31: ='TK bản thảo'!D33 -> 0.016713092 | D31: ='TK bản thảo'!F33 -> 0 | E31: =D31-C31 -> -0.016713092 | F31: =IF(C31=0,"–",D31/C31) -> 0
B33: C. Tạp vụ – tái phân bố Nội dung (% trong Tạp vụ mỗi giai đoạn)
B34: Nội dung chính | C34: Potteaux % | D34: TVK % | E34: Đ (điểm %) | F34: Tỉ số TVK/Pott
B35: ='TK bản thảo'!B38 -> Chính trị – hành chính | C35: ='TK bản thảo'!D38 -> 0.044568245 | D35: ='TK bản thảo'!F38 -> 0.020979021 | E35: =D35-C35 -> -0.023589224 | F35: =IF(C35=0,"–",D35/C35) -> 0.47071678
B36: ='TK bản thảo'!B39 -> Pháp luật – tư pháp – an ninh | C36: ='TK bản thảo'!D39 -> 0.13927577 | D36: ='TK bản thảo'!F39 -> 0.090909091 | E36: =D36-C36 -> -0.048366675 | F36: =IF(C36=0,"–",D36/C36) -> 0.65272727
B37: ='TK bản thảo'!B40 -> Quân sự – chiến sự | C37: ='TK bản thảo'!D40 -> 0.094707521 | D37: ='TK bản thảo'!F40 -> 0 | E37: =D37-C37 -> -0.094707521 | F37: =IF(C37=0,"–",D37/C37) -> 0
B38: ='TK bản thảo'!B41 -> Ngoại giao – quan hệ đối ngoại | C38: ='TK bản thảo'!D41 -> 0.019498607 | D38: ='TK bản thảo'!F41 -> 0 | E38: =D38-C38 -> -0.019498607 | F38: =IF(C38=0,"–",D38/C38) -> 0
B39: ='TK bản thảo'!B42 -> Kinh tế – tài chính – thương mại | C39: ='TK bản thảo'!D42 -> 0.15041783 | D39: ='TK bản thảo'!F42 -> 0.12587413 | E39: =D39-C39 -> -0.024543701 | F39: =IF(C39=0,"–",D39/C39) -> 0.83682984
B40: ='TK bản thảo'!B43 -> Nông nghiệp – sản xuất – nghề nghiệp | C40: ='TK bản thảo'!D43 -> 0.036211699 | D40: ='TK bản thảo'!F43 -> 0.020979021 | E40: =D40-C40 -> -0.015232678 | F40: =IF(C40=0,"–",D40/C40) -> 0.57934373
B41: ='TK bản thảo'!B44 -> Giao thông – tàu thuyền – liên lạc | C41: ='TK bản thảo'!D44 -> 0.0055710306 | D41: ='TK bản thảo'!F44 -> 0.041958042 | E41: =D41-C41 -> 0.036387011 | F41: =IF(C41=0,"–",D41/C41) -> 7.5314685
B42: ='TK bản thảo'!B45 -> Y tế – sức khỏe | C42: ='TK bản thảo'!D45 -> 0.013927577 | D42: ='TK bản thảo'!F45 -> 0 | E42: =D42-C42 -> -0.013927577 | F42: =IF(C42=0,"–",D42/C42) -> 0
B43: ='TK bản thảo'!B46 -> Giáo dục – khoa cử | C43: ='TK bản thảo'!D46 -> 0.04178273 | D43: ='TK bản thảo'!F46 -> 0.006993007 | E43: =D43-C43 -> -0.034789723 | F43: =IF(C43=0,"–",D43/C43) -> 0.16736597
B44: ='TK bản thảo'!B47 -> Văn hóa – xã hội – phong tục – đời sống | C44: ='TK bản thảo'!D47 -> 0.18384401 | D44: ='TK bản thảo'!F47 -> 0.16783217 | E44: =D44-C44 -> -0.016011843 | F44: =IF(C44=0,"–",D44/C44) -> 0.91290528
...

Sheet danh sách báo 1865-1871
A1: GIA ĐỊNH BÁO 1865–1871 — DANH SÁCH SỐ BÁO, TÌNH TRẠNG LƯU TRỮ VÀ CHÁNH TỔNG TÀI
A2: ="Tổng dự kiến: "&COUNTA(A5:A140) -> Tổng dự kiến: 136 | B2: =COUNTA(A5:A140) -> 136 | C2: ="Còn: "&COUNTIF(F5:F140,"Còn") -> Còn: 61 | D2: =COUNTIF(F5:F140,"Còn") -> 61 | E2: ="Chưa tìm thấy: "&COUNTIF(F5:F140,"Không còn/Chưa tìm thấy") -> Chưa tìm thấy: 75 | F2: =COUNTIF(F5:F140,"Không còn/Chưa tìm thấy") -> 75 | G2: Phạm vi: 1865–1871 | H2: 1865–1871 | I2: 61 số hiện còn theo PPT
A3: 1865: 3/8 1866: 10/12 1867: 12/12 1868: 7/12 1869: 16/31 1870: 10/37 1871: 3/24
A4: STT | B4: Danh sách số báo | C4: Ngày phát hành | D4: Năm phát hành | E4: Số báo | F4: Tình trạng lưu trữ | G4: Chánh tổng tài / người phụ trách | H4: Mức xác nhận ngày | I4: Ghi chú | J4: nơi bảo tồn
A5: 1 | B5: GĐB 1865-N01 | C5: 15/04/1865 | D5: 1865 | E5: 1 | F5: Không còn/Chưa tìm thấy | G5: E. Potteaux | H5: Suy ra theo lịch phát hành | I5: Chánh tổng tài ghi theo giai đoạn phụ trách, không phải xác nhận trực tiếp từ bản báo bị thiếu. | J5: =IF(F5="Còn",IF(D5=1865,"Thư viện Khoa học Tổng hợp TP.HCM; Southeast Asian Newspapers","Thư viện Quốc gia Pháp (BnF)"),"—") -> —
A6: 2 | B6: GĐB 1865-N02 | C6: 15/05/1865 | D6: 1865 | E6: 2 | F6: Không còn/Chưa tìm thấy | G6: E. Potteaux | H6: Suy ra theo lịch phát hành | I6: Chánh tổng tài ghi theo giai đoạn phụ trách, không phải xác nhận trực tiếp từ bản báo bị thiếu. | J6: =IF(F6="Còn",IF(D6=1865,"Thư viện Khoa học Tổng hợp TP.HCM; Southeast Asian Newspapers","Thư viện Quốc gia Pháp (BnF)"),"—") -> —
A7: 3 | B7: GĐB 1865-N03 | C7: 15/06/1865 | D7: 1865 | E7: 3 | F7: Không còn/Chưa tìm thấy | G7: E. Potteaux | H7: Suy ra theo lịch phát hành | I7: Chánh tổng tài ghi theo giai đoạn phụ trách, không phải xác nhận trực tiếp từ bản báo bị thiếu. | J7: =IF(F7="Còn",IF(D7=1865,"Thư viện Khoa học Tổng hợp TP.HCM; Southeast Asian Newspapers","Thư viện Quốc gia Pháp (BnF)"),"—") -> —
A8: 4 | B8: GĐB 1865-N04 | C8: 15/07/1865 | D8: 1865 | E8: 4 | F8: Còn | G8: E. Potteaux | H8: Đối chiếu — PPT chưa xác nhận ngày | I8: N4 được xác nhận còn, nhưng PPT ghi ngày N4 chưa xác nhận; 15/07 lấy từ bảng Excel hiện tại/lịch tháng. | J8: =IF(F8="Còn",IF(D8=1865,"Thư viện Khoa học Tổng hợp TP.HCM; Southeast Asian Newspapers","Thư viện Quốc gia Pháp (BnF)"),"—") -> Thư viện Khoa học Tổng hợp TP.HCM; Southeast Asian Newspapers
A9: 5 | B9: GĐB 1865-N05 | C9: 15/08/1865 | D9: 1865 | E9: 5 | F9: Còn | G9: E. Potteaux | H9: Xác nhận từ tư liệu hiện có | J9: =IF(F9="Còn",IF(D9=1865,"Thư viện Khoa học Tổng hợp TP.HCM; Southeast Asian Newspapers","Thư viện Quốc gia Pháp (BnF)"),"—") -> Thư viện Khoa học Tổng hợp TP.HCM; Southeast Asian Newspapers
A10: 6 | B10: GĐB 1865-N06 | C10: 15/10/1865 | D10: 1865 | E10: 6 | F10: Còn | G10: E. Potteaux | H10: Xác nhận từ tư liệu hiện có | I10: PPT hiệu chỉnh ngày thành 15/10/1865; Excel nội dung cũ ghi 15/09/1865. | J10: =IF(F10="Còn",IF(D10=1865,"Thư viện Khoa học Tổng hợp TP.HCM; Southeast Asian Newspapers","Thư viện Quốc gia Pháp (BnF)"),"—") -> Thư viện Khoa học Tổng hợp TP.HCM; Southeast Asian Newspapers
A11: 7 | B11: GĐB 1865-N07 | C11: 15/11/1865 | D11: 1865 | E11: 7 | F11: Không còn/Chưa tìm thấy | G11: E. Potteaux | H11: Suy ra theo lịch phát hành | I11: Chánh tổng tài ghi theo giai đoạn phụ trách, không phải xác nhận trực tiếp từ bản báo bị thiếu. | J11: =IF(F11="Còn",IF(D11=1865,"Thư viện Khoa học Tổng hợp TP.HCM; Southeast Asian Newspapers","Thư viện Quốc gia Pháp (BnF)"),"—") -> —
A12: 8 | B12: GĐB 1865-N08 | C12: 15/12/1865 | D12: 1865 | E12: 8 | F12: Không còn/Chưa tìm thấy | G12: E. Potteaux | H12: Suy ra theo lịch phát hành | I12: Chánh tổng tài ghi theo giai đoạn phụ trách, không phải xác nhận trực tiếp từ bản báo bị thiếu. | J12: =IF(F12="Còn",IF(D12=1865,"Thư viện Khoa học Tổng hợp TP.HCM; Southeast Asian Newspapers","Thư viện Quốc gia Pháp (BnF)"),"—") -> —
A13: 9 | B13: GĐB 1866-N01 | C13: 15/01/1866 | D13: 1866 | E13: 1 | F13: Còn | G13: E. Potteaux | H13: Xác nhận từ tư liệu hiện có | J13: =IF(F13="Còn",IF(D13=1865,"Thư viện Khoa học Tổng hợp TP.HCM; Southeast Asian Newspapers","Thư viện Quốc gia Pháp (BnF)"),"—") -> Thư viện Quốc gia Pháp (BnF)
A14: 10 | B14: GĐB 1866-N02 | C14: 15/02/1866 | D14: 1866 | E14: 2 | F14: Còn | G14: E. Potteaux | H14: Xác nhận từ tư liệu hiện có | J14: =IF(F14="Còn",IF(D14=1865,"Thư viện Khoa học Tổng hợp TP.HCM; Southeast Asian Newspapers","Thư viện Quốc gia Pháp (BnF)"),"—") -> Thư viện Quốc gia Pháp (BnF)
A15: 11 | B15: GĐB 1866-N03 | C15: 15/03/1866 | D15: 1866 | E15: 3 | F15: Còn | G15: E. Potteaux | H15: Xác nhận từ tư liệu hiện có | J15: =IF(F15="Còn",IF(D15=1865,"Thư viện Khoa học Tổng hợp TP.HCM; Southeast Asian Newspapers","Thư viện Quốc gia Pháp (BnF)"),"—") -> Thư viện Quốc gia Pháp (BnF)
A16: 12 | B16: GĐB 1866-N04 | C16: 15/04/1866 | D16: 1866 | E16: 4 | F16: Còn | G16: E. Potteaux | H16: Xác nhận từ tư liệu hiện có | J16: =IF(F16="Còn",IF(D16=1865,"Thư viện Khoa học Tổng hợp TP.HCM; Southeast Asian Newspapers","Thư viện Quốc gia Pháp (BnF)"),"—") -> Thư viện Quốc gia Pháp (BnF)
A17: 13 | B17: GĐB 1866-N05 | C17: 15/05/1866 | D17: 1866 | E17: 5 | F17: Còn | G17: E. Potteaux | H17: Xác nhận từ tư liệu hiện có | J17: =IF(F17="Còn",IF(D17=1865,"Thư viện Khoa học Tổng hợp TP.HCM; Southeast Asian Newspapers","Thư viện Quốc gia Pháp (BnF)"),"—") -> Thư viện Quốc gia Pháp (BnF)
A18: 14 | B18: GĐB 1866-N06 | C18: 15/06/1866 | D18: 1866 | E18: 6 | F18: Còn | G18: E. Potteaux | H18: Xác nhận từ tư liệu hiện có | J18: =IF(F18="Còn",IF(D18=1865,"Thư viện Khoa học Tổng hợp TP.HCM; Southeast Asian Newspapers","Thư viện Quốc gia Pháp (BnF)"),"—") -> Thư viện Quốc gia Pháp (BnF)
A19: 15 | B19: GĐB 1866-N07 | C19: 15/07/1866 | D19: 1866 | E19: 7 | F19: Còn | G19: E. Potteaux | H19: Xác nhận từ tư liệu hiện có | J19: =IF(F19="Còn",IF(D19=1865,"Thư viện Khoa học Tổng hợp TP.HCM; Southeast Asian Newspapers","Thư viện Quốc gia Pháp (BnF)"),"—") -> Thư viện Quốc gia Pháp (BnF)
A20: 16 | B20: GĐB 1866-N08 | C20: 15/08/1866 | D20: 1866 | E20: 8 | F20: Còn | G20: E. Potteaux | H20: Xác nhận từ tư liệu hiện có | J20: =IF(F20="Còn",IF(D20=1865,"Thư viện Khoa học Tổng hợp TP.HCM; Southeast Asian Newspapers","Thư viện Quốc gia Pháp (BnF)"),"—") -> Thư viện Quốc gia Pháp (BnF)
A21: 17 | B21: GĐB 1866-N09 | C21: 15/10/1866 | D21: 1866 | E21: 9 | F21: Còn | G21: E. Potteaux | H21: Xác nhận từ tư liệu hiện có | I21: Tên file/tư liệu hiện có ghi 15/10/1866; vì vậy không tự suy ngày N10–N11. | J21: =IF(F21="Còn",IF(D21=1865,"Thư viện Khoa học Tổng hợp TP.HCM; Southeast Asian Newspapers","Thư viện Quốc gia Pháp (BnF)"),"—") -> Thư viện Quốc gia Pháp (BnF)
A22: 18 | B22: GĐB 1866-N10 | C22: Chưa xác định | D22: 1866 | E22: 10 | F22: Không còn/Chưa tìm thấy | G22: E. Potteaux | H22: Chưa xác định | I22: Chánh tổng tài ghi theo giai đoạn phụ trách, không phải xác nhận trực tiếp từ bản báo bị thiếu. | J22: =IF(F22="Còn",IF(D22=1865,"Thư viện Khoa học Tổng hợp TP.HCM; Southeast Asian Newspapers","Thư viện Quốc gia Pháp (BnF)"),"—") -> —
A23: 19 | B23: GĐB 1866-N11 | C23: Chưa xác định | D23: 1866 | E23: 11 | F23: Không còn/Chưa tìm thấy | G23: E. Potteaux | H23: Chưa xác định | I23: Chánh tổng tài ghi theo giai đoạn phụ trách, không phải xác nhận trực tiếp từ bản báo bị thiếu. | J23: =IF(F23="Còn",IF(D23=1865,"Thư viện Khoa học Tổng hợp TP.HCM; Southeast Asian Newspapers","Thư viện Quốc gia Pháp (BnF)"),"—") -> —
A24: 20 | B24: GĐB 1866-N12 | C24: 15/12/1866 | D24: 1866 | E24: 12 | F24: Còn | G24: E. Potteaux | H24: Xác nhận từ tư liệu hiện có | J24: =IF(F24="Còn",IF(D24=1865,"Thư viện Khoa học Tổng hợp TP.HCM; Southeast Asian Newspapers","Thư viện Quốc gia Pháp (BnF)"),"—") -> Thư viện Quốc gia Pháp (BnF)
A25: 21 | B25: GĐB 1867-N01 | C25: 15/01/1867 | D25: 1867 | E25: 1 | F25: Còn | G25: E. Potteaux | H25: Xác nhận từ tư liệu hiện có | J25: =IF(F25="Còn",IF(D25=1865,"Thư viện Khoa học Tổng hợp TP.HCM; Southeast Asian Newspapers","Thư viện Quốc gia Pháp (BnF)"),"—") -> Thư viện Quốc gia Pháp (BnF)
A26: 22 | B26: GĐB 1867-N02 | C26: 15/02/1867 | D26: 1867 | E26: 2 | F26: Còn | G26: E. Potteaux | H26: Xác nhận từ tư liệu hiện có | J26: =IF(F26="Còn",IF(D26=1865,"Thư viện Khoa học Tổng hợp TP.HCM; Southeast Asian Newspapers","Thư viện Quốc gia Pháp (BnF)"),"—") -> Thư viện Quốc gia Pháp (BnF)
A27: 23 | B27: GĐB 1867-N03 | C27: 15/03/1867 | D27: 1867 | E27: 3 | F27: Còn | G27: E. Potteaux | H27: Xác nhận từ tư liệu hiện có | J27: =IF(F27="Còn",IF(D27=1865,"Thư viện Khoa học Tổng hợp TP.HCM; Southeast Asian Newspapers","Thư viện Quốc gia Pháp (BnF)"),"—") -> Thư viện Quốc gia Pháp (BnF)
A28: 24 | B28: GĐB 1867-N04 | C28: 15/04/1867 | D28: 1867 | E28: 4 | F28: Còn | G28: E. Potteaux | H28: Xác nhận từ tư liệu hiện có | J28: =IF(F28="Còn",IF(D28=1865,"Thư viện Khoa học Tổng hợp TP.HCM; Southeast Asian Newspapers","Thư viện Quốc gia Pháp (BnF)"),"—") -> Thư viện Quốc gia Pháp (BnF)
A29: 25 | B29: GĐB 1867-N05 | C29: 15/05/1867 | D29: 1867 | E29: 5 | F29: Còn | G29: E. Potteaux | H29: Xác nhận từ tư liệu hiện có | J29: =IF(F29="Còn",IF(D29=1865,"Thư viện Khoa học Tổng hợp TP.HCM; Southeast Asian Newspapers","Thư viện Quốc gia Pháp (BnF)"),"—") -> Thư viện Quốc gia Pháp (BnF)
A30: 26 | B30: GĐB 1867-N06 | C30: 15/06/1867 | D30: 1867 | E30: 6 | F30: Còn | G30: E. Potteaux | H30: Xác nhận từ tư liệu hiện có | J30: =IF(F30="Còn",IF(D30=1865,"Thư viện Khoa học Tổng hợp TP.HCM; Southeast Asian Newspapers","Thư viện Quốc gia Pháp (BnF)"),"—") -> Thư viện Quốc gia Pháp (BnF)
A31: 27 | B31: GĐB 1867-N07 | C31: 15/07/1867 | D31: 1867 | E31: 7 | F31: Còn | G31: E. Potteaux | H31: Xác nhận từ tư liệu hiện có | J31: =IF(F31="Còn",IF(D31=1865,"Thư viện Khoa học Tổng hợp TP.HCM; Southeast Asian Newspapers","Thư viện Quốc gia Pháp (BnF)"),"—") -> Thư viện Quốc gia Pháp (BnF)
A32: 28 | B32: GĐB 1867-N08 | C32: 15/08/1867 | D32: 1867 | E32: 8 | F32: Còn | G32: E. Potteaux | H32: Xác nhận từ tư liệu hiện có | J32: =IF(F32="Còn",IF(D32=1865,"Thư viện Khoa học Tổng hợp TP.HCM; Southeast Asian Newspapers","Thư viện Quốc gia Pháp (BnF)"),"—") -> Thư viện Quốc gia Pháp (BnF)
A33: 29 | B33: GĐB 1867-N09 | C33: 15/09/1867 | D33: 1867 | E33: 9 | F33: Còn | G33: E. Potteaux | H33: Xác nhận từ tư liệu hiện có | J33: =IF(F33="Còn",IF(D33=1865,"Thư viện Khoa học Tổng hợp TP.HCM; Southeast Asian Newspapers","Thư viện Quốc gia Pháp (BnF)"),"—") -> Thư viện Quốc gia Pháp (BnF)
A34: 30 | B34: GĐB 1867-N10 | C34: 15/10/1867 | D34: 1867 | E34: 10 | F34: Còn | G34: E. Potteaux | H34: Xác nhận từ tư liệu hiện có | J34: =IF(F34="Còn",IF(D34=1865,"Thư viện Khoa học Tổng hợp TP.HCM; Southeast Asian Newspapers","Thư viện Quốc gia Pháp (BnF)"),"—") -> Thư viện Quốc gia Pháp (BnF)
A35: 31 | B35: GĐB 1867-N11 | C35: 15/11/1867 | D35: 1867 | E35: 11 | F35: Còn | G35: E. Potteaux | H35: Xác nhận từ tư liệu hiện có | J35: =IF(F35="Còn",IF(D35=1865,"Thư viện Khoa học Tổng hợp TP.HCM; Southeast Asian Newspapers","Thư viện Quốc gia Pháp (BnF)"),"—") -> Thư viện Quốc gia Pháp (BnF)
... A37: 33 | B37: GĐB 1868-N01 | C37: 15/01/1868 | D37: 1868 | E37: 1 | F37: Còn | G37: E. Potteaux | H37: Xác nhận từ tư liệu hiện có | J37: =IF(F37="Còn",IF(D37=1865,"Thư viện Khoa học Tổng hợp TP.HCM; Southeast Asian Newspapers","Thư viện Quốc gia Pháp (BnF)"),"—") -> Thư viện Quốc gia Pháp (BnF)
A38: 34 | B38: GĐB 1868-N02 | C38: 15/02/1868 | D38: 1868 | E38: 2 | F38: Không còn/Chưa tìm thấy | G38: E. Potteaux | H38: Suy ra theo lịch phát hành | I38: Chánh tổng tài ghi theo giai đoạn phụ trách, không phải xác nhận trực tiếp từ bản báo bị thiếu. | J38: =IF(F38="Còn",IF(D38=1865,"Thư viện Khoa học Tổng hợp TP.HCM; Southeast Asian Newspapers","Thư viện Quốc gia Pháp (BnF)"),"—") -> —
A39: 35 | B39: GĐB 1868-N03 | C39: 15/03/1868 | D39: 1868 | E39: 3 | F39: Còn | G39: E. Potteaux | H39: Xác nhận từ tư liệu hiện có | J39: =IF(F39="Còn",IF(D39=1865,"Thư viện Khoa học Tổng hợp TP.HCM; Southeast Asian Newspapers","Thư viện Quốc gia Pháp (BnF)"),"—") -> Thư viện Quốc gia Pháp (BnF)
A40: 36 | B40: GĐB 1868-N04 | C40: 15/04/1868 | D40: 1868 | E40: 4 | F40: Còn | G40: E. Potteaux | H40: Xác nhận từ tư liệu hiện có | J40: =IF(F40="Còn",IF(D40=1865,"Thư viện Khoa học Tổng hợp TP.HCM; Southeast Asian Newspapers","Thư viện Quốc gia Pháp (BnF)"),"—") -> Thư viện Quốc gia Pháp (BnF)
A41: 37 | B41: GĐB 1868-N05 | C41: 15/05/1868 | D41: 1868 | E41: 5 | F41: Còn | G41: E. Potteaux | H41: Xác nhận từ tư liệu hiện có | J41: =IF(F41="Còn",IF(D41=1865,"Thư viện Khoa học Tổng hợp TP.HCM; Southeast Asian Newspapers","Thư viện Quốc gia Pháp (BnF)"),"—") -> Thư viện Quốc gia Pháp (BnF)
...

Sheet GDB 1866-1871
A1: DATE | B1: N0 | C1: Chánh tổng tài | D1: Mục | E1: Tên bài (nếu có) | F1: Tên đặt tạm thời | G1: Hình thức chính | H1: Hình thức phụ | I1: Nội dung chính | J1: Nội dung phụ | K1: Từ khoá | L1: Tóm tắt nội dung | M1: Ghi chú phân loại | N1: OCR | O1: Người đăng bài | P1: Người gửi bài (chuẩn hóa) | Q1: Nhóm | R1: Thời kỳ | S1: Năm (phụ) | T1: Mục (chuẩn hóa) | V1: Khóa ngày (yyyymmdd)
A2: 15/07/1865 | B2: 4 | C2: E.POTTEAUX | D2: Công vụ | E2: Không có | F2: Cuộc chạy đua ngày 25 tháng 6 (thể lệ và giải thưởng) | G2: Văn bản công quyền – quy phạm – quyết định | I2: Văn hóa – xã hội – phong tục – đời sống | K2: đua xe bò; đua lừa; đua ngựa Annam; thể lệ cuộc đua; giải thưởng; ngày 25 tháng 6 | L2: Thông báo thể lệ cuộc đua ngày 25 tháng 6 Annam (giờ thứ 6 rưỡi sáng): cuộc 1 đua xe bò (~1.000 m, giải 150/50/25 quan); cuộc 2 đua lừa (~1.500 m, 200/80/25); cuộc 3 đua ngựa Annam do người Annam cỡi mặc đồ Annam (300/100/50); cuộc 4 đua ngựa Mán/Chàm/Quảng-đông (400/100); cuộc 5 đua chung ngựa các nước (2.500 m, 1.000/100). Kèm các quy định ghi danh, ba người phán xử, cách trao giải. | M2: Thông báo thể lệ + giải thưởng cuộc đua; có quy định ghi danh/phán xử → HT: Văn bản công quyền – quy phạm – quyết định; ND: Văn hóa – xã hội – phong tục – đời sống (sự kiện đua). | R2: Potteaux | S2: =IFERROR(VALUE(RIGHT(TRIM(A2),4)),"") -> 1865 | T2: =IF(TRIM(D2)="Tập vụ","Tạp vụ",TRIM(D2)) -> Công vụ | V2: =IF($A2="","",VALUE(MID($A2,7,4)&MID($A2,4,2)&MID($A2,1,2))) -> 18650715
A3: 15/07/1865 | B3: 4 | C3: E.POTTEAUX | D3: Công vụ | E3: Không có | F3: Hội-đồng canh nông – khuyến khích nông nghiệp và nghề nghiệp | G3: Nghị luận – bình luận – khuyến dụ – giáo huấn | I3: Nông nghiệp – sản xuất – nghề nghiệp | K3: hội đồng canh nông; khuyến nông; đấu xảo; nghề nghiệp; noi gương Pha-lang-sa; phát thưởng | L3: Bài giới thiệu Hội-đồng lập sổ các giống cây trồng, vật nuôi, so sánh cách làm với các nước để khuyến khích dân cải tiến canh nông và nghề nghiệp; noi gương Pha-lang-sa lập hội thưởng để dân đua nhau chăm chỉ; sẽ tổ chức trưng bày (đấu xảo) và phát thưởng công bằng cho người làm ruộng, làm nghề giỏi. | M3: Bài khuyến khích cải tiến canh nông/nghề nghiệp → nghị luận–khuyến dụ; nội dung nông nghiệp–nghề nghiệp. | R3: Potteaux | S3: =IFERROR(VALUE(RIGHT(TRIM(A3),4)),"") -> 1865 | T3: =IF(TRIM(D3)="Tập vụ","Tạp vụ",TRIM(D3)) -> Công vụ | V3: =IF($A3="","",VALUE(MID($A3,7,4)&MID($A3,4,2)&MID($A3,1,2))) -> 18650715
A4: 15/07/1865 | B4: 4 | C4: E.POTTEAUX | D4: Công vụ | E4: Không có | F4: Tin tổng hợp: ông Boresse về Tây; tàu La-Guerrière; tha tù phát lưu | G4: Tin tổng hợp | H4: Tin – tường thuật sự kiện | I4: Đa chủ đề | K4: ông Boresse về Tây; tàu La-Guerrière; tha tù phát lưu; Vua Tự-Đức chuộc tù; Bắc-kinh – Nhựt-bổn | L4: Ông Boresse (quan Bộ Gia-định) về Pháp mồng 7 tháng này; tàu chiến La-Guerrière tới Sài-gòn rồi đi Bắc-kinh/Nhựt-bổn; tin một số tù phát lưu được tha nhờ công nghiệp, gởi thơ về nhà; đồn rằng Vua Tự-Đức chuộc tù. | M4: Ba việc độc lập (quan về Pháp, tàu chiến, tha tù), không lĩnh vực nào chi phối → tin tổng hợp; nội dung Đa chủ đề. | R4: Potteaux | S4: =IFERROR(VALUE(RIGHT(TRIM(A4),4)),"") -> 1865 | T4: =IF(TRIM(D4)="Tập vụ","Tạp vụ",TRIM(D4)) -> Công vụ | V4: =IF($A4="","",VALUE(MID($A4,7,4)&MID($A4,4,2)&MID($A4,1,2))) -> 18650715
A5: 15/07/1865 | B5: 4 | C5: E.POTTEAUX | D5: Công vụ | E5: Không có | F5: Tin các nơi: Hoàng-đế Pha-lang-sa, tàu La-place, mùa màng, xã trưởng ăn hối lộ | G5: Tin tổng hợp | H5: Tin – tường thuật sự kiện | I5: Đa chủ đề | K5: tàu La-place; Hoàng-đế Pha-lang-sa; xã trưởng ăn hối lộ; ruộng muối Chợ-bến; mùa lúa; Tham-biện Tân-an | L5: Tàu La-place về Sài-gòn đem tin Hoàng-đế Pha-lang-sa còn ở Alger; tàu máy kéo ghe vào Chợ-lớn; mưa nhiều hơn năm ngoái hứa hẹn mùa lúa tốt; xã trưởng Kiên-sảng (xã Danh) ăn tiền hối lộ của dân bị xử; nhà buôn Pháp mua gai; ruộng muối Chợ-bến phát cho dân; Tham-biện Tân-an dời sở qua làng Bình-lập; yết thị treo giải cuộc đua ngày 25/6. | M5: Nhiều tin địa phương độc lập, không lĩnh vực nào chi phối → tin tổng hợp; nội dung Đa chủ đề. | R5: Potteaux | S5: =IFERROR(VALUE(RIGHT(TRIM(A5),4)),"") -> 1865 | T5: =IF(TRIM(D5)="Tập vụ","Tạp vụ",TRIM(D5)) -> Công vụ | V5: =IF($A5="","",VALUE(MID($A5,7,4)&MID($A5,4,2)&MID($A5,1,2))) -> 18650715
A6: 15/07/1865 | B6: 4 | C6: E.POTTEAUX | D6: Công vụ | E6: CHUYỆN TÀU MITRAILLE | F6: – đi bắt tàu ô gần Bình-thuận | G6: Tin – tường thuật sự kiện | I6: Pháp luật – tư pháp – an ninh | J6: Quân sự – chiến sự | K6: tàu Mitraille; bắt tàu ô; cướp biển Bình-thuận; ghe buôn tự vệ; E. Potteaux | L6: Ngày 29 tháng 4 tàu Mitraille đưa quan Tuần-phủ Bình-thuận ra tỉnh, nhân tiện đi tuần bắt tàu ô (cướp biển); hỏi dân biết nơi có cướp thì chạy tới cửa phá; nhiều ghe buôn có súng để tự vệ. Ký: E. Potteaux, thông ngôn. | O6: E POTTEAUX | P6: E. Potteaux | Q6: Tòa soạn | R6: Potteaux | S6: =IFERROR(VALUE(RIGHT(TRIM(A6),4)),"") -> 1865 | T6: =IF(TRIM(D6)="Tập vụ","Tạp vụ",TRIM(D6)) -> Công vụ | V6: =IF($A6="","",VALUE(MID($A6,7,4)&MID($A6,4,2)&MID($A6,1,2))) -> 18650715
A7: 15/07/1865 | B7: 4 | C7: E.POTTEAUX | D7: Tạp vụ | E7: Không có | F7: Lễ kiệu ảnh tại nhà thờ Sài-gòn (22 tháng 5) | G7: Tin – tường thuật sự kiện | I7: Tôn giáo – tín ngưỡng | J7: Văn hóa – xã hội – phong tục – đời sống | K7: lễ kiệu ảnh; nhà thờ Sài-gòn; rước Mình Thánh Chúa; người Khách múa rồng; quan Nguyên-Soái; Paulus Của | L7: Ngày 22 tháng 5 tại nhà thờ nhà nước Sài-gòn có lễ kiệu ảnh (rước Mình Thánh Chúa) trọng thể: các bổn đạo, thầy cả, học trò trường Pha-lang-sa, cầm cờ lọng; người Khách (Hoa) múa rồng; đông người đi coi; quan Nguyên-Soái và các quan chực hầu tại Cầu-quan. Ký: Paulus Của. | M7: Thuật lễ kiệu ảnh tại nhà thờ Sài-gòn → tin sự kiện; tôn giáo, phụ văn hóa–xã hội. | O7: pauluscua | P7: Paulus Của (Huỳnh Tịnh Của) | Q7: Tòa soạn | R7: Potteaux | S7: =IFERROR(VALUE(RIGHT(TRIM(A7),4)),"") -> 1865 | T7: =IF(TRIM(D7)="Tập vụ","Tạp vụ",TRIM(D7)) -> Tạp vụ | V7: =IF($A7="","",VALUE(MID($A7,7,4)&MID($A7,4,2)&MID($A7,1,2))) -> 18650715
A8: 15/07/1865 | B8: 4 | C8: E.POTTEAUX | D8: Tạp vụ | E8: Không có | F8: Bắt tàu ô; tình hình mùa màng và bang giao | G8: Tin tổng hợp | I8: Đa chủ đề | K8: bắt tàu ô; mùa màng tốt; bang giao Annam – Pha-lang-sa; tịch súng đạn; Paulus Của | L8: Tháng trước bắt 5 chiếc tàu ô giao quan án Sài-gòn (tha 1, tịch súng đạn 2 chiếc rồi tha...); năm nay mưa thuận mùa màng tốt, dân đã yên hơn trước; bàn về việc hai nước Annam–Pha-lang-sa hòa hảo, Vua Annam đã hiểu tài sức Pha-lang-sa. Ký: Paulus Của. | M8: Bắt tàu ô + mùa màng + bang giao, đa lĩnh vực → tin tổng hợp; nội dung Đa chủ đề. | O8: pauluscua | P8: Paulus Của (Huỳnh Tịnh Của) | Q8: Tòa soạn | R8: Potteaux | S8: =IFERROR(VALUE(RIGHT(TRIM(A8),4)),"") -> 1865 | T8: =IF(TRIM(D8)="Tập vụ","Tạp vụ",TRIM(D8)) -> Tạp vụ | V8: =IF($A8="","",VALUE(MID($A8,7,4)&MID($A8,4,2)&MID($A8,1,2))) -> 18650715
A9: 15/07/1865 | B9: 4 | C9: E.POTTEAUX | D9: Công vụ | E9: Không có | F9: Việc làm sổ bộ dân và điều tra nghề nghiệp, ruộng đất | G9: Tin – tường thuật sự kiện | I9: Chính trị – hành chính | J9: Nông nghiệp – sản xuất – nghề nghiệp | K9: làm sổ bộ dân; điều tra nghề nghiệp; ruộng đất; làng Bình-hòa Gò-vấp; tiền thưởng làm ruộng; Paulus Của | L9: Chính quyền Pha-lang-sa muốn nắm rõ dân tình: nghề nghiệp, ruộng vườn; tháng trước quan Thượng-thơ sai Phủ Sài-gòn vào làng Bình-hòa Gò-vấp làm sổ (biên nam phụ lão ấu, tứ nghệ); quan đang lo đúc tiền thưởng hạng nhất/nhì/ba cho người làm ruộng, làm nghề giỏi. Ký: Paulus Của. | M9: Thuật việc lập sổ bộ dân, điều tra nghề nghiệp/ruộng đất → tin sự kiện; hành chính, phụ nông nghiệp–nghề nghiệp. | O9: pauluscua | P9: Paulus Của (Huỳnh Tịnh Của) | Q9: Tòa soạn | R9: Potteaux | S9: =IFERROR(VALUE(RIGHT(TRIM(A9),4)),"") -> 1865 | T9: =IF(TRIM(D9)="Tập vụ","Tạp vụ",TRIM(D9)) -> Công vụ | V9: =IF($A9="","",VALUE(MID($A9,7,4)&MID($A9,4,2)&MID($A9,1,2))) -> 18650715
A10: 15/07/1865 | B10: 4 | C10: E.POTTEAUX | D10: Tạp vụ | E10: Không có | F10: Vụ án giết lính Ma-tà tại làng Đức-lập | G10: Tin – tường thuật sự kiện | I10: Pháp luật – tư pháp – an ninh | K10: án giết lính Ma-tà; làng Đức-lập; Chợ-lớn; điều tra; Paulus Của | L10: Mồng 9 tháng 5 nhuần gặp một tên Ma-tà (lính) bị đâm lòi ruột bỏ tại làng Đức-lập gần mé sông Chợ-lớn; đang điều tra. Ký: Paulus Của. | M10: Thuật vụ giết lính Ma-tà, đang điều tra → tin sự kiện; pháp luật–an ninh. | R10: Potteaux | S10: =IFERROR(VALUE(RIGHT(TRIM(A10),4)),"") -> 1865 | T10: =IF(TRIM(D10)="Tập vụ","Tạp vụ",TRIM(D10)) -> Tạp vụ | V10: =IF($A10="","",VALUE(MID($A10,7,4)&MID($A10,4,2)&MID($A10,1,2))) -> 18650715
A11: 15/07/1865 | B11: 4 | C11: E.POTTEAUX | D11: Tạp vụ | E11: Không có | F11: Thông báo nhận bài đăng trước mồng 7 tháng Tây | G11: Thông báo – yết thị | I11: Báo chí – xuất bản – truyền thông | K11: thông báo nhà in; hạn gởi bài mồng 7 tháng Tây; sắp chữ; Paulus Tôi | L11: Từ nay ai muốn đăng chuyện vào nhựt trình phải gởi trước ngày mồng 7 tháng Tây vì một mình người sắp chữ không làm kịp. Ký: Paulus Tôi (thợ sắp chữ nhà in). | M11: Nhà in thông báo hạn gởi bài → thông báo–yết thị; nội dung Báo chí–xuất bản–truyền thông. | O11: paulus toi | P11: Paulus Tỏi | Q11: Tòa soạn / nhà in | R11: Potteaux | S11: =IFERROR(VALUE(RIGHT(TRIM(A11),4)),"") -> 1865 | T11: =IF(TRIM(D11)="Tập vụ","Tạp vụ",TRIM(D11)) -> Tạp vụ | V11: =IF($A11="","",VALUE(MID($A11,7,4)&MID($A11,4,2)&MID($A11,1,2))) -> 18650715
A12: 15/07/1865 | B12: 4 | C12: E.POTTEAUX | D12: Tạp vụ | E12: Không có | F12: Vụ đò giết người khách tại Ong-bé | G12: Tin – tường thuật sự kiện | I12: Pháp luật – tư pháp – an ninh | K12: vụ đò giết người; người khách Triều-châu; Ong-bé; quan Án Sài-gòn; Paulus Của | L12: Quan Án Sài-gòn đang tra vụ đò giết người các chú (Hoa) tại Ong-bé; mồng 8 tháng này có tên khách Triều-châu ở Chợ-lớn đi ra ngoài tàu. Ký: Paulus Của. | M12: Thuật vụ đò giết người khách, quan Án tra → tin sự kiện; pháp luật–an ninh. | O12: palus cua | P12: Paulus Của (Huỳnh Tịnh Của) | Q12: Tòa soạn | R12: Potteaux | S12: =IFERROR(VALUE(RIGHT(TRIM(A12),4)),"") -> 1865 | T12: =IF(TRIM(D12)="Tập vụ","Tạp vụ",TRIM(D12)) -> Tạp vụ | V12: =IF($A12="","",VALUE(MID($A12,7,4)&MID($A12,4,2)&MID($A12,1,2))) -> 18650715
A13: 15/07/1865 | B13: 4 | C13: E.POTTEAUX | D13: Tạp vụ | E13: Không có | F13: Giá chợ: Phú-cương | G13: Bảng giá – bảng kê – danh sách – thống kê | I13: Kinh tế – tài chính – thương mại | K13: giá chợ; Phú-cương; gạo lúa; trâu bò; giá cả | L13: Giá tại chợ Phú-cương: gạo 7 quan/vuông, lúa 5 quan 5, trâu 150 quan, bò 90 quan. | M13: Bảng giá chợ Phú-cương (hàng hóa + giá) → bảng giá/thống kê; kinh tế–thương mại. | R13: Potteaux | S13: =IFERROR(VALUE(RIGHT(TRIM(A13),4)),"") -> 1865 | T13: =IF(TRIM(D13)="Tập vụ","Tạp vụ",TRIM(D13)) -> Tạp vụ | V13: =IF($A13="","",VALUE(MID($A13,7,4)&MID($A13,4,2)&MID($A13,1,2))) -> 18650715
A14: 15/07/1865 | B14: 4 | C14: E.POTTEAUX | D14: Tạp vụ | E14: Không có | F14: Giá chợ: Phước-chánh | G14: Bảng giá – bảng kê – danh sách – thống kê | I14: Kinh tế – tài chính – thương mại | K14: giá chợ; Phước-chánh; gạo lúa; muối; đường trắng | L14: Giá tại chợ Phước-chánh: gạo 7 quan, lúa 3 quan 5, muối, đường trắng. | M14: Bảng giá chợ Phước-chánh → bảng giá/thống kê; kinh tế–thương mại. | R14: Potteaux | S14: =IFERROR(VALUE(RIGHT(TRIM(A14),4)),"") -> 1865 | T14: =IF(TRIM(D14)="Tập vụ","Tạp vụ",TRIM(D14)) -> Tạp vụ | V14: =IF($A14="","",VALUE(MID($A14,7,4)&MID($A14,4,2)&MID($A14,1,2))) -> 18650715
A15: 15/07/1865 | B15: 4 | C15: E.POTTEAUX | D15: Tạp vụ | E15: Không có | F15: Giá chợ: Mỹ-tho | G15: Bảng giá – bảng kê – danh sách – thống kê | I15: Kinh tế – tài chính – thương mại | K15: giá chợ; Mỹ-tho; Kiên-hòa Kiên-hưng; gạo; giá cả | L15: Giá tại Mỹ-tho và các huyện Kiên-hòa/Kiên-hưng/Kiên-đặng/Kiên-phong: gạo 6–6,7 quan/vuông. | M15: Bảng giá chợ Mỹ-tho và các huyện → bảng giá/thống kê; kinh tế–thương mại. | R15: Potteaux | S15: =IFERROR(VALUE(RIGHT(TRIM(A15),4)),"") -> 1865 | T15: =IF(TRIM(D15)="Tập vụ","Tạp vụ",TRIM(D15)) -> Tạp vụ | V15: =IF($A15="","",VALUE(MID($A15,7,4)&MID($A15,4,2)&MID($A15,1,2))) -> 18650715
A16: 15/07/1865 | B16: 4 | C16: E.POTTEAUX | D16: Tạp vụ | E16: Không có | F16: Long-thành | G16: Bảng giá – bảng kê – danh sách – thống kê | I16: Kinh tế – tài chính – thương mại | K16: giá chợ; Long-thành; gạo lúa; đường trắng đen; giá cả | L16: Giá hàng hóa tại Long-thành: gạo 16 quan/tạ, lúa 3 quan 7, đường trắng/đen. | M16: Bảng giá hàng hóa Long-thành → bảng giá/thống kê; kinh tế–thương mại. | R16: Potteaux | S16: =IFERROR(VALUE(RIGHT(TRIM(A16),4)),"") -> 1865 | T16: =IF(TRIM(D16)="Tập vụ","Tạp vụ",TRIM(D16)) -> Tạp vụ | V16: =IF($A16="","",VALUE(MID($A16,7,4)&MID($A16,4,2)&MID($A16,1,2))) -> 18650715
A17: 15/08/1865 | B17: 5 | C17: E.POTTEAUX | D17: Công vụ | E17: CÔNG VỤ | F17: Ban bằng cấp thật thọ cho các cai tổng có công; khen thưởng các làng giữ dân; thử nghiệm nghề tằm tơ | G17: Tin tổng hợp | I17: Chính trị – hành chính | J17: Nông nghiệp – sản xuất – nghề nghiệp | K17: bằng cấp thật thọ; cai tổng có công; khen thưởng làng giữ dân; nghề tằm tơ; Định-tường; nguyệt bổng 45 quan | L17: Nhân lễ khánh hạ Đức Hoàng-đế Pha-lang-sa, quan Nguyên-Soái ban bằng cấp "thật thọ" cho các cai tổng lâu năm có công, được lãnh bổng 45 quan/tháng (theo lệ lương cựu trào cấp cho biện binh khi trước). Báo sẽ biên riêng danh sách các cai tổng, lý trưởng, hương chức người Annam có công giúp dân. Khen thôn trưởng, hương chức các làng Mi-tra, Vinh-quới, Lộc-thuận, Phú-vạn (tỉnh Định-tường) đã giữ dân khỏi trộm cướp và bè đảng loạn (ngày 30 tháng nhuận ngũ nguyệt); quan Nguyên-Soái gởi lời thăm và ban thưởng riêng cho người có công. Từ tháng sau sẽ kê danh sách tù được tha nhân dịp lễ. Lãnh sự Pha-lang-sa tại Nhựt-bổn gởi tằm và giống cây nuôi tằm về thử nghiệm nghề làm tơ. | M17: Ban bằng cấp cai tổng + khen làng giữ dân + thử nghề tằm tơ → tin tổng hợp; hành chính, phụ nông nghiệp. | R17: Potteaux | S17: =IFERROR(VALUE(RIGHT(TRIM(A17),4)),"") -> 1865 | T17: =IF(TRIM(D17)="Tập vụ","Tạp vụ",TRIM(D17)) -> Công vụ | V17: =IF($A17="","",VALUE(MID($A17,7,4)&MID($A17,4,2)&MID($A17,1,2))) -> 18650815
A18: 15/08/1865 | B18: 5 | C18: E.POTTEAUX | D18: Công vụ | E18: Không có | F18: Bán đấu giá 12 ngựa dư dụng; bổ nhiệm tri huyện Kiên-phong; địa điểm cuộc đua ngày 25 tháng 6 | G18: Tin tổng hợp | I18: Đa chủ đề | K18: đấu giá 12 ngựa; trại ngựa Sài-gòn; tri huyện Kiên-phong; Trần-bá-Lộc; cuộc đua Mó-súng | L18: Ngày 26 tháng 5 nhuận yết thị bán đấu giá 12 con ngựa dư dụng tại trại ngựa Sài-gòn (mồng 2 tháng 6, giờ thứ 8 ban mai); người mua phải giao bạc trong 24 giờ rồi lãnh biên. Ngày 27 tháng 5 nhuận quan Nguyên-Soái thưởng công Trần-bá-Lộc, cho làm tri huyện Kiên-phong (Định-tường) thế Lê-Nhựt-Tuyên (xin phép về nghỉ), đồng thời cấp bằng cho Lê-Nhựt-Tuyên hồi hưu. Cuộc đua ngựa/xe bò ngày 25 tháng 6 định tổ chức tại Mó-súng, ngoài đồng tập trận. | M18: Đấu giá ngựa + bổ nhiệm + địa điểm đua, đa lĩnh vực → tin tổng hợp; nội dung Đa chủ đề. | R18: Potteaux | S18: =IFERROR(VALUE(RIGHT(TRIM(A18),4)),"") -> 1865 | T18: =IF(TRIM(D18)="Tập vụ","Tạp vụ",TRIM(D18)) -> Công vụ | V18: =IF($A18="","",VALUE(MID($A18,7,4)&MID($A18,4,2)&MID($A18,1,2))) -> 18650815
A19: 15/08/1865 | B19: 5 | C19: E.POTTEAUX | D19: Công vụ | E19: CHUYỆN TỔNG-BINH LUẬN | F19: Tội ác của Tổng-binh Trương-văn-Luận ở huyện Tân-hòa | G19: Tin – tường thuật sự kiện | I19: Pháp luật – tư pháp – an ninh | J19: Quân sự – chiến sự | K19: Tổng-binh Trương-văn-Luận; huyện Tân-hòa; tội ác giặc; Quản-định; nạn nhân bị giết; Gò-công | L19: Trương-văn-Luận (huyện Tân-hòa) làm đầu giặc không ra thú, vốn là bạn với Quản-định; từ Gò-công năm 1863 được Quản-định cho làm Tổng-binh, sau nhóm lấy chức Đề-đốc. Khi Quản-định chết, Luận tự làm chủ, sanh sát dữ dội, giục người làm điều tội ác trong huyện Tân-hòa; đã giết mấy mươi người. Báo kể một số nạn nhân: Đội Chi (Bình-tân), Xã Hữu và Xoai (hương chức Bình-luông-tây), Điền (Thuận-tắc), Nhiêu Vinh-lợi, Khề, và Lộc (Bình-ân) cả vợ cùng hai con bị đốt sống vì đi báo quan chỗ giấu súng. Luận đã xưng hết mọi tội ác, thiên hạ đều hay biết. | M19: Thuật tội ác giặc Trương-văn-Luận (giết nhiều người) → tin sự kiện; pháp luật–an ninh, phụ quân sự. | R19: Potteaux | S19: =IFERROR(VALUE(RIGHT(TRIM(A19),4)),"") -> 1865 | T19: =IF(TRIM(D19)="Tập vụ","Tạp vụ",TRIM(D19)) -> Công vụ | V19: =IF($A19="","",VALUE(MID($A19,7,4)&MID($A19,4,2)&MID($A19,1,2))) -> 18650815
A20: 15/08/1865 | B20: 5 | C20: E.POTTEAUX | D20: Công vụ | E20: Không có | F20: Định thuế điền tổng Thanh-phong (huyện Kiên-hòa, Mỹ-tho) | G20: Văn bản công quyền – quy phạm – quyết định | I20: Kinh tế – tài chính – thương mại | K20: định thuế điền; tổng Thanh-phong; huyện Kiên-hòa; Mỹ-tho; 9.209 quan | L20: Quan Nguyên-Soái chuẩn cho tổng Thanh-phong (huyện Kiên-hòa, tỉnh Mỹ-tho) nạp thuế điền theo mức mỗi vuông gạo 5 quan 5 tiền, tổng cộng 9.209 quan 7 tiền rưỡi, phải lo nạp cho cấp kỳ. | M20: Quyết định mức thuế điền tổng Thanh-phong → văn bản công quyền/quyết định; kinh tế–tài chính (thuế). Ranh giới tin/quyết định – cần rà. | R20: Potteaux | S20: =IFERROR(VALUE(RIGHT(TRIM(A20),4)),"") -> 1865 | T20: =IF(TRIM(D20)="Tập vụ","Tạp vụ",TRIM(D20)) -> Công vụ | V20: =IF($A20="","",VALUE(MID($A20,7,4)&MID($A20,4,2)&MID($A20,1,2))) -> 18650815
A21: 15/08/1865 | B21: 5 | C21: E.POTTEAUX | D21: Công vụ | E21: NGÀY MỒNG 9 THÁNG 6 | F21: Thưởng ban biện Khánh và làng Mi-tra chống đảng ngụy | G21: Văn bản công quyền – quy phạm – quyết định | I21: Pháp luật – tư pháp – an ninh | J21: Chính trị – hành chính | K21: thưởng ban biện Khánh; làng Mi-tra; chống đảng ngụy; đồng hồ; khí giới tự vệ; 1.000 quan | L21: Quan Nguyên-Soái thưởng ban biện Khánh (làng Mi-tra) một cái đồng hồ vì ngày 29 tháng 5 nhuần đã đốc sức dân đánh lui một đảng ngụy tới phá làng. Xét làng Mi-tra gan dạ, có lòng bền chặt với nhà nước, quan chuẩn cho làng sắm khí giới tự vệ; súng, thuốc, đạn lãnh tại quan Tỉnh-đốc Mỹ-tho. Do làng chịu tổn thất khi cự với đảng ngụy, quan ban cho làng 1.000 quan tiền để trợ giúp. | M21: Công bố thưởng/chuẩn/ban cho làng Mi-tra chống đảng ngụy → VBCQ/quyết định; thưởng vì giữ an ninh/chống loạn nên an ninh chính, phụ hành chính. | R21: Potteaux | S21: =IFERROR(VALUE(RIGHT(TRIM(A21),4)),"") -> 1865 | T21: =IF(TRIM(D21)="Tập vụ","Tạp vụ",TRIM(D21)) -> Công vụ | V21: =IF($A21="","",VALUE(MID($A21,7,4)&MID($A21,4,2)&MID($A21,1,2))) -> 18650815
